Workbook
Name \\\\: #REF!
Name \\\\\: #REF!
Name \0: #REF!
Name \A: #REF!
Name \A: #REF!
Name \A: #REF!
Name \b: #REF!
Name \c: #REF!
Name \c: #REF!
Name \Ch1: #REF!
Name \d: #REF!
Name \DS: #REF!
Name \e: #REF!
Name \e: #REF!
Name \f: #REF!
Name \GGO: #REF!
Name \h: #REF!
Name \i: #REF!
Name \l: #REF!
Name \l: #REF!
Name \M: #REF!
Name \M: #REF!
Name \mm: #REF!
Name \N: #REF!
Name \N: #REF!
Name \o: #REF!
Name \o: #REF!
Name \OPCOES: #REF!
Name \P: #REF!
Name \P: #REF!
Name \pop: #REF!
Name \q: #REF!
Name \r: #REF!
Name \s: #REF!
Name \s: #REF!
Name \t: #REF!
Name \u: #REF!
Name \v: #REF!
Name \w: #REF!
Name \x: #REF!
Name \y: #REF!
Name \z: #REF!
Name _: #REF!
Name _.: #REF!
Name __: #REF!
Name ___: #REF!
Name ____: #REF!
Name _____: #REF!
Name ______: #REF!
Name _______: #REF!
Name _______res1: #REF!
Name _______res1: #REF!
Name _______res1: #REF!
Name _______res1: #REF!
Name _______res1: #REF!
Name _______res1: #REF!
Name _______res1: [1]Sheet7!#REF!
Name _______sft2: #REF!
Name _______sft2: #REF!
Name _______sft2: #REF!

Sheet Resume
G3: =Pricing!G3 -> Description
F4: =Pricing!F4 -> Client: CTS | G4: =Pricing!G4 -> Offer: 251.1009.R03
F5: =Pricing!F5 -> Responsible: QS Manager | G5: =Pricing!G5 -> Date: 31/10/2025
A7: # | E7: Item | F7: Description | I7: Total Price | J7: %
A8: # | I8: =IF(G8<>0,#REF!+#REF!,"")
A9: # | E9: 216 | F9: =+VLOOKUP(E9,Pricing!E:M,2,0) -> Administration / supervision | I9: =VLOOKUP(E9,Pricing!E:M,9,0) -> 40885876 | J9: =I9/$I$31 -> 0.17433402
A10: # | E10: 211 | F10: =+VLOOKUP(E10,Pricing!E:M,2,0) -> Logistics | I10: =VLOOKUP(E10,Pricing!E:M,9,0) -> 0 | J10: =I10/$I$31 -> 0
A11: # | E11: 419 | F11: =+VLOOKUP(E11,Pricing!E:M,2,0) -> Commisioning | I11: =VLOOKUP(E11,Pricing!E:M,9,0) -> 10636532 | J11: =I11/$I$31 -> 0.045353299
A12: # | E12: 218 | F12: =+VLOOKUP(E12,Pricing!E:M,2,0) -> Site infrastruckture | I12: =VLOOKUP(E12,Pricing!E:M,9,0) -> 6650953.5 | J12: =I12/$I$31 -> 0.028359121
A13: # | E13: 411 | F13: =+VLOOKUP(E13,Pricing!E:M,2,0) -> Containment | I13: =VLOOKUP(E13,Pricing!E:M,9,0) -> 60103897 | J13: =I13/$I$31 -> 0.25627809
A14: # | E14: 412 | F14: =+VLOOKUP(E14,Pricing!E:M,2,0) -> Earthing inside, outside and underground | I14: =VLOOKUP(E14,Pricing!E:M,9,0) -> 8917705.6 | J14: =I14/$I$31 -> 0.038024366
A15: # | E15: 413 | F15: =+VLOOKUP(E15,Pricing!E:M,2,0) -> Lightning protection | I15: =VLOOKUP(E15,Pricing!E:M,9,0) -> 2756131.2 | J15: =I15/$I$31 -> 0.011751917
A16: # | E16: 414 | F16: =+VLOOKUP(E16,Pricing!E:M,2,0) -> Equipment installation | I16: =VLOOKUP(E16,Pricing!E:M,9,0) -> 2538511.9 | J16: =I16/$I$31 -> 0.010824007
A17: # | E17: 429 | F17: =+VLOOKUP(E17,Pricing!E:M,2,0) -> Cables MV | I17: =VLOOKUP(E17,Pricing!E:M,9,0) -> 0 | J17: =I17/$I$31 -> 0
A18: # | E18: 431 | F18: =+VLOOKUP(E18,Pricing!E:M,2,0) -> Busbars | I18: =VLOOKUP(E18,Pricing!E:M,9,0) -> 0 | J18: =I18/$I$31 -> 0
A19: # | E19: 432 | F19: =+VLOOKUP(E19,Pricing!E:M,2,0) -> Cables LV | I19: =VLOOKUP(E19,Pricing!E:M,9,0) -> 42802556 | J19: =I19/$I$31 -> 0.18250659
A20: # | E20: 433 | F20: =+VLOOKUP(E20,Pricing!E:M,2,0) -> Small power | I20: =VLOOKUP(E20,Pricing!E:M,9,0) -> 4680321.8 | J20: =I20/$I$31 -> 0.019956508
... A29: # | E29: 21 | F29: =+VLOOKUP(E29,Pricing!E:M,2,0) -> Fibre Optic | I29: =VLOOKUP(E29,Pricing!E:M,9,0) -> 0 | J29: =I29/$I$31 -> 0
A30: # | E30: 22 | F30: Roxtec | I30: =VLOOKUP(E30,Pricing!E:M,9,0) -> 4211871.3 | J30: =I30/$I$31 -> 0.017959074
A31: # | F31: Total | I31: =SUBTOTAL(9,I8:I30) -> 2.3452609e+08 | J31: =SUM(J9:J30) -> 1
F33: Add VAT at the legal rate, if applicable.
F35: EXCLUDE:
F36: Any and all equipment and work not mentioned in the proposal
F38: PAYMENT CONDITIONS:
F39: 20%: at Purchase Order signature
F40: 75%: within 30 days - working progress
F41: 5%: within 30 days - after completion of the work
F43: Trond Nygaard
F44: Velox Electro Nordics AS

Sheet Pricing
M1: =M508 -> 2.3452609e+08 | AD1: =SUM(AD8:AD508) -> 2217.9769 | AE1: Persons | AF1: Week | AG1: Months
AE2: =AD1/AF2 -> 42.653403 | AF2: =52 -> 52 | AG2: =AF2/4.2 -> 12.380952
G3: Description | M3: Prices in NOK
F4: ='Project Input'!B2 & " " &'Project Input'!C2 -> Client: CTS | G4: Offer: 251.1009.R03 | P4: =SUBTOTAL(9,P8:P507) -> 92490232 | U4: =SUM(U8:U508) -> 1.0418915e+08 | W4: =SUBTOTAL(9,W8:W507) -> 1.9667939e+08 | Z4: =SUBTOTAL(9,Z8:Z508) -> 100547.4 | AA4: =SUBTOTAL(9,AA8:AA508) -> 27975.44 | AB4: =SUBTOTAL(9,AB8:AB508) -> 31171.5 | AC4: =SUBTOTAL(9,AC8:AC508) -> 159694.34
F5: ='Project Input'!B3 & " " &'Project Input'!C3 -> Responsible: QS Manager | G5: Date: 31/10/2025 | P5: =P4/W4 -> 0.47025891 | U5: =U4/W4 -> 0.52974109
I6: Material | K6: Labor | O6: Material | R6: Manpower | W6: Total Cost | Z6: Sum Hours | AA6: Sum Hours | AB6: Sum Hours | AC6: Sum Hours
E7: Item | F7: Description | G7: Qt. | H7: Unit. | I7: Unit. Price | J7: Total Price | K7: Unit. Price | L7: Total Price | M7: Total Price | O7: Unit. Cost | P7: Sum Cost | R7: Average | S7: Electrician | T7: Test/Commiss | U7: Sum Cost | X7: OBS.: | Z7: Average | AA7: Electrician | AB7: Test/Commiss | AD7: 1 HR/1Wk
I8: =IF(G8<>"",O8/(1-($O$1+#REF!)),"") | J8: =IF(G8<>"",G8*I8,"") | K8: =IF(G8<>0,(U8/G8)/(1-('Project Input'!$C$16+'Project Input'!$C$17)),"") | L8: =IF(G8<>0,K8*G8,"") | M8: =IF(G8<>0,J8+L8,"") | P8: =IF(G8<>"",G8*O8,"") | U8: =IF(G8<>"",(R8*G8*'Project Input'!$C$47)+(S8*G8*'Project Input'!$C$46)+(T8*G8*'Project Input'!$C$45),"") | W8: =IF(G8<>"",U8+P8,"") | Z8: =R8*G8 -> 0 | AA8: =S8*G8 -> 0 | AB8: =T8*G8 -> 0 | AC8: =SUM(Z8:AB8) -> 0 | AD8: =IF(G8<>"",AC8/'Project Input'!$C$41,"")
E9: 216 | F9: Administration / supervision | J9: =IF(G9<>"",G9*I9,"") | K9: =IF(H9<>"",H9*J9,"") | L9: =IF(I9<>"",I9*K9,"") | M9: =SUBTOTAL(9,M10:M26) -> 40885876 | P9: =IF(G9<>"",G9*O9,"") | U9: =IF(G9<>"",(R9*G9*'Project Input'!$C$47)+(S9*G9*'Project Input'!$C$46)+(T9*G9*'Project Input'!$C$45),"") | W9: =IF(G9<>"",U9+P9,"") | Z9: =R9*G9 -> 0 | AA9: =S9*G9 -> 0 | AB9: =T9*G9 -> 0 | AC9: =SUM(Z9:AB9) -> 0 | AD9: =IF(G9<>"",AC9/'Project Input'!$C$41,"")
I10: =IF(G10<>"",O10/(1-('Project Input'!$C$20+'Project Input'!$C$21)),"") | J10: =IF(G10<>"",G10*I10,"") | K10: =IF(G10<>0,(U10/G10)/(1-('Project Input'!$C$20+'Project Input'!$C$21)),"") | L10: =IF(G10<>0,K10*G10,"") | M10: =IF(G10<>0,J10+L10,"") | P10: =IF(G10<>"",G10*O10,"") | U10: =IF(G10<>"",(R10*G10*'Project Input'!$C$47)+(S10*G10*'Project Input'!$C$46)+(T10*G10*'Project Input'!$C$45),"") | W10: =IF(G10<>"",U10+P10,"") | Z10: =R10*G10 -> 0 | AA10: =S10*G10 -> 0 | AB10: =T10*G10 -> 0 | AC10: =SUM(Z10:AB10) -> 0 | AD10: =IF(G10<>"",AC10/'Project Input'!$C$41,"")
F11: Project managment(Project director and manager) | G11: 1 | H11: un | I11: =IF(G11<>"",O11/(1-('Project Input'!$C$20+'Project Input'!$C$21)),"") -> 0 | J11: =IF(G11<>"",G11*I11,"") -> 0 | K11: =IF(G11<>0,(U11/G11)/(1-('Project Input'!$C$20+'Project Input'!$C$21)),"") -> 3358164.5 | L11: =IF(G11<>0,K11*G11,"") -> 3358164.5 | M11: =IF(G11<>0,J11+L11,"") -> 3358164.5 | P11: =IF(G11<>"",G11*O11,"") -> 0 | T11: 3500 | U11: =IF(G11<>"",(R11*G11*'Project Input'!$C$47)+(S11*G11*'Project Input'!$C$46)+(T11*G11*'Project Input'!$C$45),"") -> 2817500 | W11: =IF(G11<>"",U11+P11,"") -> 2817500 | Z11: =R11*G11 -> 0 | AA11: =S11*G11 -> 0 | AB11: =T11*G11 -> 3500 | AC11: =SUM(Z11:AB11) -> 3500 | AD11: =IF(G11<>"",AC11/'Project Input'!$C$41,"") -> 48.611111
F12: Site electrical engineers | G12: 3 | H12: un | I12: =IF(G12<>"",O12/(1-('Project Input'!$C$20+'Project Input'!$C$21)),"") -> 0 | J12: =IF(G12<>"",G12*I12,"") -> 0 | K12: =IF(G12<>0,(U12/G12)/(1-('Project Input'!$C$20+'Project Input'!$C$21)),"") -> 2398688.9 | L12: =IF(G12<>0,K12*G12,"") -> 7196066.7 | M12: =IF(G12<>0,J12+L12,"") -> 7196066.7 | T12: 2500 | U12: =IF(G12<>"",(R12*G12*'Project Input'!$C$47)+(S12*G12*'Project Input'!$C$46)+(T12*G12*'Project Input'!$C$45),"") -> 6037500 | W12: =IF(G12<>"",U12+P12,"") -> 6037500 | Z12: =R12*G12 -> 0 | AA12: =S12*G12 -> 0 | AB12: =T12*G12 -> 7500 | AC12: =SUM(Z12:AB12) -> 7500 | AD12: =IF(G12<>"",AC12/'Project Input'!$C$41,"") -> 104.16667
F13: Design support engineers | G13: 1 | H13: un | I13: =IF(G13<>"",O13/(1-('Project Input'!$C$20+'Project Input'!$C$21)),"") -> 0 | J13: =IF(G13<>"",G13*I13,"") -> 0 | K13: =IF(G13<>0,(U13/G13)/(1-('Project Input'!$C$20+'Project Input'!$C$21)),"") -> 2206793.8 | L13: =IF(G13<>0,K13*G13,"") -> 2206793.8 | M13: =IF(G13<>0,J13+L13,"") -> 2206793.8 | P13: =IF(G13<>"",G13*O13,"") -> 0 | T13: 2300 | U13: =IF(G13<>"",(R13*G13*'Project Input'!$C$47)+(S13*G13*'Project Input'!$C$46)+(T13*G13*'Project Input'!$C$45),"") -> 1851500 | W13: =IF(G13<>"",U13+P13,"") -> 1851500 | Z13: =R13*G13 -> 0 | AA13: =S13*G13 -> 0 | AB13: =T13*G13 -> 2300 | AC13: =SUM(Z13:AB13) -> 2300 | AD13: =IF(G13<>"",AC13/'Project Input'!$C$41,"") -> 31.944444
F14: Procurment officer | G14: 1 | H14: un | I14: =IF(G14<>"",O14/(1-('Project Input'!$C$20+'Project Input'!$C$21)),"") -> 0 | J14: =IF(G14<>"",G14*I14,"") -> 0 | K14: =IF(G14<>0,(U14/G14)/(1-('Project Input'!$C$20+'Project Input'!$C$21)),"") -> 2398688.9 | L14: =IF(G14<>0,K14*G14,"") -> 2398688.9 | M14: =IF(G14<>0,J14+L14,"") -> 2398688.9 | P14: =IF(G14<>"",G14*O14,"") -> 0 | T14: 2500 | U14: =IF(G14<>"",(R14*G14*'Project Input'!$C$47)+(S14*G14*'Project Input'!$C$46)+(T14*G14*'Project Input'!$C$45),"") -> 2012500 | W14: =IF(G14<>"",U14+P14,"") -> 2012500 | Z14: =R14*G14 -> 0 | AA14: =S14*G14 -> 0 | AB14: =T14*G14 -> 2500 | AC14: =SUM(Z14:AB14) -> 2500 | AD14: =IF(G14<>"",AC14/'Project Input'!$C$41,"") -> 34.722222
F15: Planner and document controller | G15: 1 | H15: un | I15: =IF(G15<>"",O15/(1-('Project Input'!$C$20+'Project Input'!$C$21)),"") -> 0 | J15: =IF(G15<>"",G15*I15,"") -> 0 | K15: =IF(G15<>0,(U15/G15)/(1-('Project Input'!$C$20+'Project Input'!$C$21)),"") -> 722884.39 | L15: =IF(G15<>0,K15*G15,"") -> 722884.39 | M15: =IF(G15<>0,J15+L15,"") -> 722884.39 | P15: =IF(G15<>"",G15*O15,"") -> 0 | R15: 1000 | U15: =IF(G15<>"",(R15*G15*'Project Input'!$C$47)+(S15*G15*'Project Input'!$C$46)+(T15*G15*'Project Input'!$C$45),"") -> 606500 | W15: =IF(G15<>"",U15+P15,"") -> 606500 | Z15: =R15*G15 -> 1000 | AA15: =S15*G15 -> 0 | AB15: =T15*G15 -> 0 | AC15: =SUM(Z15:AB15) -> 1000 | AD15: =IF(G15<>"",AC15/'Project Input'!$C$41,"") -> 13.888889
F16: Site Supervisors | G16: 4 | H16: un | I16: =IF(G16<>"",O16/(1-('Project Input'!$C$20+'Project Input'!$C$21)),"") -> 0 | J16: =IF(G16<>"",G16*I16,"") -> 0 | K16: =IF(G16<>0,(U16/G16)/(1-('Project Input'!$C$20+'Project Input'!$C$21)),"") -> 1929380.2 | L16: =IF(G16<>0,K16*G16,"") -> 7717520.9 | M16: =IF(G16<>0,J16+L16,"") -> 7717520.9 | P16: =IF(G16<>"",G16*O16,"") -> 0 | S16: 2500 | U16: =IF(G16<>"",(R16*G16*'Project Input'!$C$47)+(S16*G16*'Project Input'!$C$46)+(T16*G16*'Project Input'!$C$45),"") -> 6475000 | W16: =IF(G16<>"",U16+P16,"") -> 6475000 | Z16: =R16*G16 -> 0 | AA16: =S16*G16 -> 10000 | AB16: =T16*G16 -> 0 | AC16: =SUM(Z16:AB16) -> 10000 | AD16: =IF(G16<>"",AC16/'Project Input'!$C$41,"") -> 138.88889
F17: Formen/team leaders | G17: 1 | H17: un | I17: =IF(G17<>"",O17/(1-('Project Input'!$C$20+'Project Input'!$C$21)),"") -> 0 | J17: =IF(G17<>"",G17*I17,"") -> 0 | K17: =IF(G17<>0,(U17/G17)/(1-('Project Input'!$C$20+'Project Input'!$C$21)),"") -> 771752.09 | L17: =IF(G17<>0,K17*G17,"") -> 771752.09 | M17: =IF(G17<>0,J17+L17,"") -> 771752.09 | P17: =IF(G17<>"",G17*O17,"") -> 0 | S17: 1000 | U17: =IF(G17<>"",(R17*G17*'Project Input'!$C$47)+(S17*G17*'Project Input'!$C$46)+(T17*G17*'Project Input'!$C$45),"") -> 647500 | W17: =IF(G17<>"",U17+P17,"") -> 647500 | Z17: =R17*G17 -> 0 | AA17: =S17*G17 -> 1000 | AB17: =T17*G17 -> 0 | AC17: =SUM(Z17:AB17) -> 1000 | AD17: =IF(G17<>"",AC17/'Project Input'!$C$41,"") -> 13.888889
F18: HSE officers | G18: 3 | H18: un | I18: =IF(G18<>"",O18/(1-('Project Input'!$C$20+'Project Input'!$C$21)),"") -> 0 | J18: =IF(G18<>"",G18*I18,"") -> 0 | K18: =IF(G18<>0,(U18/G18)/(1-('Project Input'!$C$20+'Project Input'!$C$21)),"") -> 1807211 | L18: =IF(G18<>0,K18*G18,"") -> 5421632.9 | M18: =IF(G18<>0,J18+L18,"") -> 5421632.9 | P18: =IF(G18<>"",G18*O18,"") -> 0 | R18: 2500 | U18: =IF(G18<>"",(R18*G18*'Project Input'!$C$47)+(S18*G18*'Project Input'!$C$46)+(T18*G18*'Project Input'!$C$45),"") -> 4548750 | W18: =IF(G18<>"",U18+P18,"") -> 4548750 | Z18: =R18*G18 -> 7500 | AA18: =S18*G18 -> 0 | AB18: =T18*G18 -> 0 | AC18: =SUM(Z18:AB18) -> 7500 | AD18: =IF(G18<>"",AC18/'Project Input'!$C$41,"") -> 104.16667
F19: PPE and HSE equipment | G19: 1 | H19: un | I19: =IF(G19<>"",O19/(1-('Project Input'!$C$20+'Project Input'!$C$21)),"") -> 893921.33 | J19: =IF(G19<>"",G19*I19,"") -> 893921.33 | K19: =IF(G19<>0,(U19/G19)/(1-('Project Input'!$C$20+'Project Input'!$C$21)),"") -> 0 | L19: =IF(G19<>0,K19*G19,"") -> 0 | M19: =IF(G19<>0,J19+L19,"") -> 893921.33 | O19: 750000 | P19: =IF(G19<>"",G19*O19,"") -> 750000 | U19: =IF(G19<>"",(R19*G19*'Project Input'!$C$47)+(S19*G19*'Project Input'!$C$46)+(T19*G19*'Project Input'!$C$45),"") -> 0 | W19: =IF(G19<>"",U19+P19,"") -> 750000 | Z19: =R19*G19 -> 0 | AA19: =S19*G19 -> 0 | AB19: =T19*G19 -> 0 | AC19: =SUM(Z19:AB19) -> 0 | AD19: =IF(G19<>"",AC19/'Project Input'!$C$41,"") -> 0
F20: Logistics officer | G20: 1 | H20: un | I20: =IF(G20<>"",O20/(1-('Project Input'!$C$20+'Project Input'!$C$21)),"") -> 0 | J20: =IF(G20<>"",G20*I20,"") -> 0 | K20: =IF(G20<>0,(U20/G20)/(1-('Project Input'!$C$20+'Project Input'!$C$21)),"") -> 479737.78 | L20: =IF(G20<>0,K20*G20,"") -> 479737.78 | M20: =IF(G20<>0,J20+L20,"") -> 479737.78 | P20: =IF(G20<>"",G20*O20,"") -> 0 | T20: 500 | U20: =IF(G20<>"",(R20*G20*'Project Input'!$C$47)+(S20*G20*'Project Input'!$C$46)+(T20*G20*'Project Input'!$C$45),"") -> 402500 | W20: =IF(G20<>"",U20+P20,"") -> 402500 | Z20: =R20*G20 -> 0 | AA20: =S20*G20 -> 0 | AB20: =T20*G20 -> 500 | AC20: =SUM(Z20:AB20) -> 500 | AD20: =IF(G20<>"",AC20/'Project Input'!$C$41,"") -> 6.9444444
F21: Workshop operator / Spotters | G21: 8 | H21: un | I21: =IF(G21<>"",O21/(1-('Project Input'!$C$20+'Project Input'!$C$21)),"") -> 0 | J21: =IF(G21<>"",G21*I21,"") -> 0 | K21: =IF(G21<>0,(U21/G21)/(1-('Project Input'!$C$20+'Project Input'!$C$21)),"") -> 361442.19 | L21: =IF(G21<>0,K21*G21,"") -> 2891537.5 | M21: =IF(G21<>0,J21+L21,"") -> 2891537.5 | P21: =IF(G21<>"",G21*O21,"") -> 0 | R21: 500 | U21: =IF(G21<>"",(R21*G21*'Project Input'!$C$47)+(S21*G21*'Project Input'!$C$46)+(T21*G21*'Project Input'!$C$45),"") -> 2426000 | W21: =IF(G21<>"",U21+P21,"") -> 2426000 | Z21: =R21*G21 -> 4000 | AA21: =S21*G21 -> 0 | AB21: =T21*G21 -> 0 | AC21: =SUM(Z21:AB21) -> 4000 | AD21: =IF(G21<>"",AC21/'Project Input'!$C$41,"") -> 55.555556
F22: Safety Supervisor LV (AFA) | G22: 1 | H22: un | I22: =IF(G22<>"",O22/(1-('Project Input'!$C$20+'Project Input'!$C$21)),"") -> 0 | J22: =IF(G22<>"",G22*I22,"") -> 0 | K22: =IF(G22<>0,(U22/G22)/(1-('Project Input'!$C$20+'Project Input'!$C$21)),"") -> 1439213.3 | L22: =IF(G22<>0,K22*G22,"") -> 1439213.3 | M22: =IF(G22<>0,J22+L22,"") -> 1439213.3 | P22: =IF(G22<>"",G22*O22,"") -> 0 | T22: 1500 | U22: =IF(G22<>"",(R22*G22*'Project Input'!$C$47)+(S22*G22*'Project Input'!$C$46)+(T22*G22*'Project Input'!$C$45),"") -> 1207500 | W22: =IF(G22<>"",U22+P22,"") -> 1207500 | Z22: =R22*G22 -> 0 | AA22: =S22*G22 -> 0 | AB22: =T22*G22 -> 1500 | AC22: =SUM(Z22:AB22) -> 1500 | AD22: =IF(G22<>"",AC22/'Project Input'!$C$41,"") -> 20.833333
F23: QA (Quality assurance specialists) | G23: 1 | I23: =IF(G23<>"",O23/(1-('Project Input'!$C$20+'Project Input'!$C$21)),"") -> 0 | J23: =IF(G23<>"",G23*I23,"") -> 0 | K23: =IF(G23<>0,(U23/G23)/(1-('Project Input'!$C$20+'Project Input'!$C$21)),"") -> 1439213.3 | L23: =IF(G23<>0,K23*G23,"") -> 1439213.3 | M23: =IF(G23<>0,J23+L23,"") -> 1439213.3 | P23: =IF(G23<>"",G23*O23,"") -> 0 | T23: 1500 | U23: =IF(G23<>"",(R23*G23*'Project Input'!$C$47)+(S23*G23*'Project Input'!$C$46)+(T23*G23*'Project Input'!$C$45),"") -> 1207500 | W23: =IF(G23<>"",U23+P23,"") -> 1207500 | Z23: =R23*G23 -> 0 | AA23: =S23*G23 -> 0 | AB23: =T23*G23 -> 1500 | AC23: =SUM(Z23:AB23) -> 1500 | AD23: =IF(G23<>"",AC23/'Project Input'!$C$41,"") -> 20.833333
F24: SJA, DRA, PTW and toolbox talks | G24: 1 | H24: ls | I24: =IF(G24<>"",O24/(1-('Project Input'!$C$20+'Project Input'!$C$21)),"") -> 0 | J24: =IF(G24<>"",G24*I24,"") -> 0 | K24: =IF(G24<>0,(U24/G24)/(1-('Project Input'!$C$20+'Project Input'!$C$21)),"") -> 3948748.5 | L24: =IF(G24<>0,K24*G24,"") -> 3948748.5 | M24: =IF(G24<>0,J24+L24,"") -> 3948748.5 | P24: =IF(G24<>"",G24*O24,"") -> 0 | R24: 2000 | S24: 2000 | T24: 1000 | U24: =IF(G24<>"",(R24*G24*'Project Input'!$C$47)+(S24*G24*'Project Input'!$C$46)+(T24*G24*'Project Input'!$C$45),"") -> 3313000 | W24: =IF(G24<>"",U24+P24,"") -> 3313000 | Z24: =R24*G24 -> 2000 | AA24: =S24*G24 -> 2000 | AB24: =T24*G24 -> 1000 | AC24: =SUM(Z24:AB24) -> 5000 | AD24: =IF(G24<>"",AC24/'Project Input'!$C$41,"") -> 69.444444
I25: =IF(G25<>"",O25/(1-('Project Input'!$C$20+'Project Input'!$C$21)),"") | J25: =IF(G25<>"",G25*I25,"") | K25: =IF(G25<>0,(U25/G25)/(1-('Project Input'!$C$20+'Project Input'!$C$21)),"") | L25: =IF(G25<>0,K25*G25,"") | M25: =IF(G25<>0,J25+L25,"") | P25: =IF(G25<>"",G25*O25,"") | U25: =IF(G25<>"",(R25*G25*'Project Input'!$C$47)+(S25*G25*'Project Input'!$C$46)+(T25*G25*'Project Input'!$C$45),"") | W25: =IF(G25<>"",U25+P25,"") | Z25: =R25*G25 -> 0 | AA25: =S25*G25 -> 0 | AB25: =T25*G25 -> 0 | AC25: =SUM(Z25:AB25) -> 0 | AD25: =IF(G25<>"",AC25/'Project Input'!$C$41,"")
I26: =IF(G26<>"",O26/(1-('Project Input'!$C$20+'Project Input'!$C$21)),"") | J26: =IF(G26<>"",G26*I26,"") | K26: =IF(G26<>0,(U26/G26)/(1-('Project Input'!$C$20+'Project Input'!$C$21)),"") | L26: =IF(G26<>0,K26*G26,"") | M26: =IF(G26<>0,J26+L26,"") | P26: =IF(G26<>"",G26*O26,"") | U26: =IF(G26<>"",(R26*G26*'Project Input'!$C$47)+(S26*G26*'Project Input'!$C$46)+(T26*G26*'Project Input'!$C$45),"") | W26: =IF(G26<>"",U26+P26,"") | Z26: =R26*G26 -> 0 | AA26: =S26*G26 -> 0 | AB26: =T26*G26 -> 0 | AC26: =SUM(Z26:AB26) -> 0 | AD26: =IF(G26<>"",AC26/'Project Input'!$C$41,"")
E27: 211 | F27: Logistics | L27: =IF(I27<>"",I27*K27,"") | M27: =SUBTOTAL(9,M28:M33) -> 0 | P27: =IF(G27<>"",G27*O27,"") | U27: =IF(G27<>"",(R27*G27*'Project Input'!$C$47)+(S27*G27*'Project Input'!$C$46)+(T27*G27*'Project Input'!$C$45),"") | W27: =IF(G27<>"",U27+P27,"") | Z27: =R27*G27 -> 0 | AA27: =S27*G27 -> 0 | AB27: =T27*G27 -> 0 | AC27: =SUM(Z27:AB27) -> 0 | AD27: =IF(G27<>"",AC27/'Project Input'!$C$41,"")
F28: travel rotation /person | G28: 0 | H28: month | I28: =IF(G28<>"",O28/(1-('Project Input'!$C$20+'Project Input'!$C$21)),"") -> 0 | J28: =IF(G28<>"",G28*I28,"") -> 0 | K28: =IF(G28<>0,(U28/G28)/(1-('Project Input'!$C$20+'Project Input'!$C$21)),"") | L28: =IF(G28<>0,K28*G28,"") | M28: =IF(G28<>0,J28+L28,"") | P28: =IF(G28<>"",G28*O28,"") -> 0 | U28: =IF(G28<>"",(R28*G28*'Project Input'!$C$47)+(S28*G28*'Project Input'!$C$46)+(T28*G28*'Project Input'!$C$45),"") -> 0 | W28: =IF(G28<>"",U28+P28,"") -> 0 | Z28: =R28*G28 -> 0 | AA28: =S28*G28 -> 0 | AB28: =T28*G28 -> 0 | AC28: =SUM(Z28:AB28) -> 0 | AD28: =IF(G28<>"",AC28/'Project Input'!$C$41,"") -> 0
F29: local travel / person | G29: 0 | H29: month | I29: =IF(G29<>"",O29/(1-('Project Input'!$C$20+'Project Input'!$C$21)),"") -> 0 | J29: =IF(G29<>"",G29*I29,"") -> 0 | K29: =IF(G29<>0,(U29/G29)/(1-('Project Input'!$C$20+'Project Input'!$C$21)),"") | L29: =IF(G29<>0,K29*G29,"") | M29: =IF(G29<>0,J29+L29,"") | P29: =IF(G29<>"",G29*O29,"") -> 0 | U29: =IF(G29<>"",(R29*G29*'Project Input'!$C$47)+(S29*G29*'Project Input'!$C$46)+(T29*G29*'Project Input'!$C$45),"") -> 0 | W29: =IF(G29<>"",U29+P29,"") -> 0 | Z29: =R29*G29 -> 0 | AA29: =S29*G29 -> 0 | AB29: =T29*G29 -> 0 | AC29: =SUM(Z29:AB29) -> 0 | AD29: =IF(G29<>"",AC29/'Project Input'!$C$41,"") -> 0
G30: 0 | H30: day | I30: =IF(G30<>"",O30/(1-('Project Input'!$C$20+'Project Input'!$C$21)),"") -> 0 | J30: =IF(G30<>"",G30*I30,"") -> 0 | K30: =IF(G30<>0,(U30/G30)/(1-('Project Input'!$C$20+'Project Input'!$C$21)),"") | L30: =IF(G30<>0,K30*G30,"") | M30: =IF(G30<>0,J30+L30,"") | P30: =IF(G30<>"",G30*O30,"") -> 0 | U30: =IF(G30<>"",(R30*G30*'Project Input'!$C$47)+(S30*G30*'Project Input'!$C$46)+(T30*G30*'Project Input'!$C$45),"") -> 0 | W30: =IF(G30<>"",U30+P30,"") -> 0 | Z30: =R30*G30 -> 0 | AA30: =S30*G30 -> 0 | AB30: =T30*G30 -> 0 | AC30: =SUM(Z30:AB30) -> 0 | AD30: =IF(G30<>"",AC30/'Project Input'!$C$41,"") -> 0
F31: Food/meal day person by CTS | G31: 0 | H31: day | I31: =IF(G31<>"",O31/(1-('Project Input'!$C$20+'Project Input'!$C$21)),"") -> 0 | J31: =IF(G31<>"",G31*I31,"") -> 0 | K31: =IF(G31<>0,(U31/G31)/(1-('Project Input'!$C$20+'Project Input'!$C$21)),"") | L31: =IF(G31<>0,K31*G31,"") | M31: =IF(G31<>0,J31+L31,"") | P31: =IF(G31<>"",G31*O31,"") -> 0 | U31: =IF(G31<>"",(R31*G31*'Project Input'!$C$47)+(S31*G31*'Project Input'!$C$46)+(T31*G31*'Project Input'!$C$45),"") -> 0 | W31: =IF(G31<>"",U31+P31,"") -> 0 | Z31: =R31*G31 -> 0 | AA31: =S31*G31 -> 0 | AB31: =T31*G31 -> 0 | AC31: =SUM(Z31:AB31) -> 0 | AD31: =IF(G31<>"",AC31/'Project Input'!$C$41,"") -> 0
I32: =IF(G32<>"",O32/(1-('Project Input'!$C$20+'Project Input'!$C$21)),"") | J32: =IF(G32<>"",G32*I32,"") | K32: =IF(G32<>0,(U32/G32)/(1-('Project Input'!$C$20+'Project Input'!$C$21)),"") | L32: =IF(G32<>0,K32*G32,"") | M32: =IF(G32<>0,J32+L32,"") | P32: =IF(G32<>"",G32*O32,"") | U32: =IF(G32<>"",(R32*G32*'Project Input'!$C$47)+(S32*G32*'Project Input'!$C$46)+(T32*G32*'Project Input'!$C$45),"") | W32: =IF(G32<>"",U32+P32,"") | Z32: =R32*G32 -> 0 | AA32: =S32*G32 -> 0 | AB32: =T32*G32 -> 0 | AC32: =SUM(Z32:AB32) -> 0 | AD32: =IF(G32<>"",AC32/'Project Input'!$C$41,"")
I33: =IF(G33<>"",O33/(1-('Project Input'!$C$20+'Project Input'!$C$21)),"") | J33: =IF(G33<>"",G33*I33,"") | K33: =IF(G33<>0,(U33/G33)/(1-('Project Input'!$C$20+'Project Input'!$C$21)),"") | L33: =IF(G33<>0,K33*G33,"") | M33: =IF(G33<>0,J33+L33,"") | P33: =IF(G33<>"",G33*O33,"") | U33: =IF(G33<>"",(R33*G33*'Project Input'!$C$47)+(S33*G33*'Project Input'!$C$46)+(T33*G33*'Project Input'!$C$45),"") | W33: =IF(G33<>"",U33+P33,"") | Z33: =R33*G33 -> 0 | AA33: =S33*G33 -> 0 | AB33: =T33*G33 -> 0 | AC33: =SUM(Z33:AB33) -> 0 | AD33: =IF(G33<>"",AC33/'Project Input'!$C$41,"")
E34: 419 | F34: Commisioning | L34: =IF(I34<>"",I34*K34,"") | M34: =SUBTOTAL(9,M35:M44) -> 10636532 | P34: =IF(G34<>"",G34*O34,"") | U34: =IF(G34<>"",(R34*G34*'Project Input'!$C$47)+(S34*G34*'Project Input'!$C$46)+(T34*G34*'Project Input'!$C$45),"") | W34: =IF(G34<>"",U34+P34,"") | Z34: =R34*G34 -> 0 | AA34: =S34*G34 -> 0 | AB34: =T34*G34 -> 0 | AC34: =SUM(Z34:AB34) -> 0 | AD34: =IF(G34<>"",AC34/'Project Input'!$C$41,"")
F35: Commissioning - Level 1, Level 2, Level 3 | G35: 1 | I35: =IF(G35<>"",O35/(1-('Project Input'!$C$20+'Project Input'!$C$21)),"") -> 357568.53 | J35: =IF(G35<>"",G35*I35,"") -> 357568.53 | K35: =IF(G35<>0,(U35/G35)/(1-('Project Input'!$C$20+'Project Input'!$C$21)),"") -> 6716329 | L35: =IF(G35<>0,K35*G35,"") -> 6716329 | M35: =IF(G35<>0,J35+L35,"") -> 7073897.5 | O35: 300000 | P35: =IF(G35<>"",G35*O35,"") -> 300000 | T35: 7000 | U35: =IF(G35<>"",(R35*G35*'Project Input'!$C$47)+(S35*G35*'Project Input'!$C$46)+(T35*G35*'Project Input'!$C$45),"") -> 5635000 | W35: =IF(G35<>"",U35+P35,"") -> 5935000 | Z35: =R35*G35 -> 0 | AA35: =S35*G35 -> 0 | AB35: =T35*G35 -> 7000 | AC35: =SUM(Z35:AB35) -> 7000 | AD35: =IF(G35<>"",AC35/'Project Input'!$C$41,"") -> 97.222222
F36: LOTO system | G36: 1 | I36: =IF(G36<>"",O36/(1-('Project Input'!$C$20+'Project Input'!$C$21)),"") -> 119189.51 | J36: =IF(G36<>"",G36*I36,"") -> 119189.51 | K36: =IF(G36<>0,(U36/G36)/(1-('Project Input'!$C$20+'Project Input'!$C$21)),"") -> 154350.42 | L36: =IF(G36<>0,K36*G36,"") -> 154350.42 | M36: =IF(G36<>0,J36+L36,"") -> 273539.93 | O36: 100000 | P36: =IF(G36<>"",G36*O36,"") -> 100000 | S36: 200 | U36: =IF(G36<>"",(R36*G36*'Project Input'!$C$47)+(S36*G36*'Project Input'!$C$46)+(T36*G36*'Project Input'!$C$45),"") -> 129500 | W36: =IF(G36<>"",U36+P36,"") -> 229500 | Z36: =R36*G36 -> 0 | AA36: =S36*G36 -> 200 | AB36: =T36*G36 -> 0 | AC36: =SUM(Z36:AB36) -> 200 | AD36: =IF(G36<>"",AC36/'Project Input'!$C$41,"") -> 2.7777778
I37: =IF(G37<>"",O37/(1-('Project Input'!$C$20+'Project Input'!$C$21)),"") | J37: =IF(G37<>"",G37*I37,"") | K37: =IF(G37<>0,(U37/G37)/(1-('Project Input'!$C$20+'Project Input'!$C$21)),"") | L37: =IF(G37<>0,K37*G37,"") | M37: =IF(G37<>0,J37+L37,"") | P37: =IF(G37<>"",G37*O37,"") | U37: =IF(G37<>"",(R37*G37*'Project Input'!$C$47)+(S37*G37*'Project Input'!$C$46)+(T37*G37*'Project Input'!$C$45),"") | W37: =IF(G37<>"",U37+P37,"") | Z37: =R37*G37 -> 0 | AA37: =S37*G37 -> 0 | AB37: =T37*G37 -> 0 | AC37: =SUM(Z37:AB37) -> 0 | AD37: =IF(G37<>"",AC37/'Project Input'!$C$41,"")
F38: Documentation, red-marks, manuals | G38: 1 | I38: =IF(G38<>"",O38/(1-('Project Input'!$C$20+'Project Input'!$C$21)),"") -> 119189.51 | J38: =IF(G38<>"",G38*I38,"") -> 119189.51 | K38: =IF(G38<>0,(U38/G38)/(1-('Project Input'!$C$20+'Project Input'!$C$21)),"") -> 287842.67 | L38: =IF(G38<>0,K38*G38,"") -> 287842.67 | M38: =IF(G38<>0,J38+L38,"") -> 407032.18 | O38: 100000 | P38: =IF(G38<>"",G38*O38,"") -> 100000 | T38: 300 | U38: =IF(G38<>"",(R38*G38*'Project Input'!$C$47)+(S38*G38*'Project Input'!$C$46)+(T38*G38*'Project Input'!$C$45),"") -> 241500 | W38: =IF(G38<>"",U38+P38,"") -> 341500 | Z38: =R38*G38 -> 0 | AA38: =S38*G38 -> 0 | AB38: =T38*G38 -> 300 | AC38: =SUM(Z38:AB38) -> 300 | AD38: =IF(G38<>"",AC38/'Project Input'!$C$41,"") -> 4.1666667
F39: Labeling of equipment | G39: 1 | I39: =IF(G39<>"",O39/(1-('Project Input'!$C$20+'Project Input'!$C$21)),"") -> 297973.78 | J39: =IF(G39<>"",G39*I39,"") -> 297973.78 | K39: =IF(G39<>0,(U39/G39)/(1-('Project Input'!$C$20+'Project Input'!$C$21)),"") -> 361442.19 | L39: =IF(G39<>0,K39*G39,"") -> 361442.19 | M39: =IF(G39<>0,J39+L39,"") -> 659415.97 | O39: 250000 | P39: =IF(G39<>"",G39*O39,"") -> 250000 | R39: 500 | U39: =IF(G39<>"",(R39*G39*'Project Input'!$C$47)+(S39*G39*'Project Input'!$C$46)+(T39*G39*'Project Input'!$C$45),"") -> 303250 | W39: =IF(G39<>"",U39+P39,"") -> 553250 | Z39: =R39*G39 -> 500 | AA39: =S39*G39 -> 0 | AB39: =T39*G39 -> 0 | AC39: =SUM(Z39:AB39) -> 500 | AD39: =IF(G39<>"",AC39/'Project Input'!$C$41,"") -> 6.9444444
I40: =IF(G40<>"",O40/(1-('Project Input'!$C$20+'Project Input'!$C$21)),"") | J40: =IF(G40<>"",G40*I40,"") | K40: =IF(G40<>0,(U40/G40)/(1-('Project Input'!$C$20+'Project Input'!$C$21)),"") | L40: =IF(G40<>0,K40*G40,"") | M40: =IF(G40<>0,J40+L40,"") | P40: =IF(G40<>"",G40*O40,"") | U40: =IF(G40<>"",(R40*G40*'Project Input'!$C$47)+(S40*G40*'Project Input'!$C$46)+(T40*G40*'Project Input'!$C$45),"") | W40: =IF(G40<>"",U40+P40,"") | Z40: =R40*G40 -> 0 | AA40: =S40*G40 -> 0 | AB40: =T40*G40 -> 0 | AC40: =SUM(Z40:AB40) -> 0 | AD40: =IF(G40<>"",AC40/'Project Input'!$C$41,"")
...

Sheet Project Input
B2: Client: | C2: CTS | E2: Estimate: | H2: Topics | J2: Deliv. | K2: Install | O2: Ratios: | P2: Cost (NOK)
B3: Responsible: | C3: QS Manager | E3: # cables BMS Gapit (Cat 6a FTP): | F3: =C5*50 -> 1250 | H3: Power Cables | J3: x | K3: x | O3: # BMS rack / MW | P3: 0.7
E4: # Power cables Gen: | F4: =27*C8 -> 27 | H4: Signal cables | J4: x | K4: x | O4: # DB / MW: | P4: 1.2
B5: MW: | C5: 25 | E5: # Access control Security Cat6 | F5: =15*C5 -> 375 | H5: Cable lugs | J5: x | K5: x | O5: 22 kV (loop between PODs) (NOK/MW) | P5: 400000
B6: Quantity of EPOD: | C6: 24 | E6: # Access control Security LiHCH 4x0,5 | F6: =3*C5 -> 75 | H6: Contaiment/cable ladders | J6: x | K6: x | O6: Access Control and Security Equipment cabling (Doors, card reader, push botton, cameras, cooling system (NOK/MW) | P6: 215000
B7: Transformer size [kVA]: | C7: 3150 | E7: # Access control Security PT 10 pair | F7: =3*C5 -> 75 | H7: Lights | J7: x | K7: x | O7: Auxiliar equipment (Aux chillers, pumps, elevators, small power cabling 630A Tap-Off…) (NOK/MW) | P7: 255000
B8: Quantity of Gen: | C8: 1 | E8: # Access control Security PT 4 pair | F8: =1*C5 -> 25 | H8: Fire detection | K8: x | O8: Average length BMS cabling: | P8: 50
B9: Power of Gen [kVA]: | C9: 3250 | E9: # Skids BMS instrumentation 4G1,5 | F9: =11*C5 -> 275 | H9: Early warning detection equipment | J9: x | K9: x | O9: Cabling CRAH, IFSI-EMC 4x6/6 (mt/MW) | P9: 250
B10: Main Switchboard sizing [A]: | C10: 4000 | E10: # Skids BMS instrumentation 7G1,5 | F10: =3*C5 -> 75 | H10: Clamps, ties, bolts etc.. | J10: x | K10: x | O10: Cabling Fan walls, IFSI-EMC 4x25/16 (mt/MW) | P10: 600
B11: Switchboard type: | C11: Form 4 Type 6 | E11: # Skids BMS instrumentation 12G1,5 | F11: =2*C5 -> 50 | H11: Tap off boxes | J11: x | K11: x | O11: Cabling to fire alarm system (NOK/m2) | P11: 215
B12: Quantity of Chiller: | C12: 38 | E12: # Skids BMS instr. Belden 79841NH | F12: =2*C5 -> 50 | H12: Install. Leak Detection | K12: x | O12: Cabling to fire alarm system (NOK/MW) | P12: 170000
B13: Quantity of Fanwall: | E13: # Skids BMS instrumentation Cat6 | F13: =3*C5 -> 75 | O13: Car Charger 11kW, 16A, 3 Phase+N; complete with cables (/un.) | P13: 15000
B14: Quantity of CRAH unit: | E14: # Fire damper KNX/BUS EIB-H 2x2x0,8 | F14: =5*C5 -> 125 | H14: CTS delivers: | O14: CCTV / camera cabeling indoor (NOK/m2) | P14: 50
B15: Quantity of DH: | E15: # PMS/Genset 12G1,5 | F15: =2*C8 -> 2 | H15: Busbars | K15: x | O15: CCTV / camera cabeling indoor (NOK/MW) | P15: 42500
B16: Rear door cooling: | E16: # PMS/Genset 5G1,5 | F16: =1*C8 -> 1 | H16: Switchboards | K16: x | O16: Control cabling to Generator (NOK/Gen) | P16: 42500
B17: Building area (m2): | C17: =5000+84+300+346 -> 5730 | E17: # PMS/Genset 3G2,5 | F17: =2*C8 -> 2 | H17: Fanwalls | O17: Documentation, red-marks, manuals (# hour/MW) | P17: 40
B18: Roof area (m2): | E18: # PMS/Genset Cat6 | F18: =1*C8 -> 1 | H18: IT racks | O18: Earthing inside building NOK/ m2: | P18: 535
E19: Number of DB - NB: | F19: =1*C6 -> 24 | H19: Chillers and cooling components | O19: Earthing inside building NOK/MW: | P19: 190000
B20: OH: | C20: =6.1% -> 0.061 | E20: Number of DB - SB: | F20: =0.5*C6 -> 12 | H20: Security and acces control components | O20: Earthing main ring underground
B21: Cost-plus (markup) | C21: 0.1 | E21: Number of DB - NB/SB: | F21: =1*C6 -> 24 | H21: Transport co | O21: Emergency lighting (NOK/MW) | P21: 140000
E22: Number of BMS rack (building): | F22: =0.5*C5 -> 12.5 | O22: Emergency lighting (centralized) NOK/m2: | P22: 365
B23: Velox Electro Nordics Labour hourly rate (Cost): | E23: # Rear door cooling | O23: Emergency lighting (centralized) NOK/MW: | P23: 127500
B24: Average: | C24: =460*1.05 -> 483 | E24: # Fanwall: | F24: =C5*6 -> 150 | O24: Emergency lighting (descentralized) NOK/m2 | P24: 340
B25: Engineer: | C25: 945 | O25: Emergency lighting (descentralized) NOK/MW | P25: 255000
B26: Supervisor: | C26: 805 | F26: /m2 | O26: General contractor administration [Project Director/Manager, Planners, HSE, Design, HR, Supervision, etc] (# hour / MW) | P26: 600
B27: Foreman: | C27: 605 | E27: lighting cabling | F27: 840 | O27: General contractor administration [Project Director/Manager, Planners, HSE, Design, HR, Supervision, etc] (NOK / MW) | P27: 600000
B28: Team leader: | C28: 605 | E28: emergency lighting | F28: 250 | O28: Heat Exchangers (control panel, flow meter, valce, PT 100 Dif pressure, Ethernet communication) (NOK/Heat Exchange) | P28: 148750
B29: Electrician/Fitter: | C29: 565 | E29: lighting cabling | F29: 450 | O29: Heat Exchangers (control panel, flow meter, valce, PT 100 Dif pressure, Ethernet communication) (NOK/MW) | P29: 51000
B30: Electrician/Fitter Assistant: | C30: 520 | O30: Heating trace (NOK/MW) | P30: 10500
B31: SW: | C31: 500 | E31: Currency NOK-€ | F31: 11.5 | O31: Hours / MW | P31: 5000
B32: NSW: | C32: 478 | O32: Installation complies with legislation (NOK/MW) | P32: 18000
E33: Variation market cooper price | F33: 1.07 | O33: Installation of fire alarm system (NOK/m2) | P33: 43
B34: External service: | C34: 730 | E34: Fitting (Bend, Union, T) average | F34: 1.3 | O34: Installation of fire alarm system (NOK/MW) | P34: 34000
E35: k installation | F35: 1.1 | O35: Instrumentation (Temperature, Pressure, Flow, Pressurization station, Levels...) (# instruments / MW) | P35: 20
B36: HR logistics Cost/Hour: | O36: Lenght containment / 1m multipole cable: | P36: 0.6
B37: Accomodation/Local travels: | O37: Lenght containment / 1m unipolar cable: | P37: 0.06
B38: Meals: | O38: Lighting Dali (Definelight) NOK/m2: | P38: 910
B39: Travels: | O39: Lighting Dali (Veko, Glamox) NOK/m2: | P39: 510
O40: Lighting indoor (NOK/MW) | P40: 425000
B41: Number hours per week | C41: 72 | O41: Lighting outoor (NOK/MW) | P41: 51000
...

Sheet Cables
E2: ='Project Input'!F31 -> 11.5
A3: Code | B3: Type | C3: Material | D3: Price/mt [NOK] | E3: Price/mt [€] | F3: Last update | K3: Pulling cable (Cu) | L3: Cable Tie/mt (€) | X3: Prysmian | Y3: Prysmian (€) | Z3: Sonepar | AA3: Sonepar (€) | AB3: Diferences (€)
B4: XLPE 500V CU | C4: 3G2,5 mm2 | D4: =E4*$E$2 -> 12.716125 | E4: =1105.75/1000 -> 1.10575 | F4: 17/2 | K4: =D93 -> 0.07 | L4: =M93 -> 0.06 | P4: "Forecast" for Hamina FI | R4: size | S4: total (m) | T4: Qty. cables | U4: Qty Terminations | V4: Average mt
B5: XLPE 0,6/1kV CU | C5: 5G2,5 mm2 | D5: =E5*$E$2 -> 19.50561 | E5: =1696.14/1000 -> 1.69614 | F5: 17/2 | K5: =D108 -> 0.12 | L5: =M108 -> 0.09 | P5: XLPE 0,6/1kV CU | Q5: 4C | R5: 2,5 | S5: 100000 | T5: 1716 | U5: 3432 | V5: 58.275058 | X5: AFUX-HF C-PRo 500V 3G2,5 RM | Y5: 0.96018989 | Z5: HHJ LiteRex C 3x2,5 S | AA5: 1.3347 | AB5: =Y5-AA5 -> -0.37451011 | AD5: ="XLPE"&" "&"CU"&" "&"-"&" "&X5&" "&AC5 -> XLPE CU - AFUX-HF C-PRo 500V 3G2,5 RM
B6: XLPE 500V CU | C6: 5G4 mm2 | D6: =E6*$E$2 -> 29.361915 | E6: =2553.21/1000 -> 2.55321 | F6: 17/2 | K6: =D107 -> 0.13 | L6: =M107 -> 0.12 | P6: XLPE 0,6/1kV CU | Q6: 4C | R6: 4 | S6: 7000 | T6: 150 | U6: 300 | V6: 46.666667 | X6: AFUX-HF C-PRo 500V 5G4 RM | Y6: 2.8853882 | Z6: MMJ-HF C 5x6 S | AA6: 4.842 | AB6: =Y6-AA6 -> -1.9566118 | AD6: ="XLPE"&" "&"CU"&" "&"-"&" "&X6&" "&AC6 -> XLPE CU - AFUX-HF C-PRo 500V 5G4 RM
B7: XLPE 0,6/1kV CU | C7: 3x 6/6 mm2 | D7: =E7*$E$2 -> 41.00279 | E7: =E8 -> 3.56546 | K7: =D91 -> 0.12 | L7: =M91 -> 0.09 | P7: XLPE 0,6/1kV CU | Q7: 4C | R7: 6 | S7: 3000 | T7: 50 | U7: 100 | V7: 60 | X7: AFUX-HF C-PRo 1kV 5G6 RM | Y7: 3.7432644 | Z7: MMJ-HF C 5x6 S | AA7: 4.842 | AB7: =Y7-AA7 -> -1.0987356 | AD7: ="XLPE"&" "&"CU"&" "&"-"&" "&X7&" "&AC7 -> XLPE CU - AFUX-HF C-PRo 1kV 5G6 RM
B8: XLPE 0,6/1kV CU | C8: 5G6 mm2 | D8: =E8*$E$2 -> 41.00279 | E8: =3565.46/1000 -> 3.56546 | F8: 17/2 | K8: =D106 -> 0.13 | L8: =M106 -> 0.12 | P8: XLPE 0,6/1kV CU | Q8: 4C | R8: 10 | S8: 1500 | T8: 20 | U8: 40 | V8: 75 | X8: AFUX-HF C-PRo 1kV 5G10 RM | Y8: 5.8280351 | Z8: MMJ-HF C 5x10 S | AA8: 7.39 | AB8: =Y8-AA8 -> -1.5619649 | AD8: ="XLPE"&" "&"CU"&" "&"-"&" "&X8&" "&AC8 -> XLPE CU - AFUX-HF C-PRo 1kV 5G10 RM
B9: XLPE 0,6/1kV CU | C9: 3x 10/10 mm2 | D9: =E9*$E$2 -> 67.330315 | E9: =E10 -> 5.85481 | K9: =D90 -> 0.13 | L9: =M90 -> 0.12 | P9: XLPE 0,6/1kV CU G/Y | Q9: 1C | R9: 16 | S9: 3400 | T9: 14 | U9: 28 | V9: 242.85714 | X9: MK-HF C-Pro 16 KEVI | Y9: 1.7539708 | Z9: MK-HF C 16 GNYE H07Z1-R TYPE 2 | AA9: 2.6687 | AB9: =Y9-AA9 -> -0.91472925 | AC9: G/Y | AD9: ="XLPE"&" "&"CU"&" "&"-"&" "&X9&" "&AC9 -> XLPE CU - MK-HF C-Pro 16 KEVI G/Y
B10: XLPE 0,6/1kV CU | C10: 5G10 mm2 | D10: =E10*$E$2 -> 67.330315 | E10: =5854.81/1000 -> 5.85481 | F10: 17/2 | K10: =D105 -> 0.13 | L10: =M105 -> 0.15 | P10: XLPE 0,6/1kV CU | Q10: 4C | R10: 16 | S10: 13160 | T10: 188 | U10: 376 | V10: 70 | X10: MCMK-HF C-PRo 4x16/16 RM 1kV | Y10: 8.9459241 | Z10: XCMK-HF C 4x16/16 | AA10: 12.2682 | AB10: =Y10-AA10 -> -3.3222759 | AD10: ="XLPE"&" "&"CU"&" "&"-"&" "&X10&" "&AC10 -> XLPE CU - MCMK-HF C-PRo 4x16/16 RM 1kV
B11: XLPE 0,6/1kV CU | C11: 3x 16/10 mm2 | D11: =E11*$E$2 -> 102.85163 | E11: =E12 -> 8.94362 | K11: =D89 -> 0.13 | L11: =M89 -> 0.12 | P11: XLPE 0,6/1kV CU G/Y | Q11: 1C | R11: 25 | S11: 3300 | T11: 12 | U11: 24 | V11: 275 | X11: MK-HF C-Pro 25 KEVI | Y11: 2.7962848 | Z11: MK-HF C 25 GNYE H07Z1-R TYPE 2 | AA11: 4.0898 | AB11: =Y11-AA11 -> -1.2935152 | AC11: G/Y | AD11: ="XLPE"&" "&"CU"&" "&"-"&" "&X11&" "&AC11 -> XLPE CU - MK-HF C-Pro 25 KEVI G/Y
B12: XLPE 0,6/1kV CU | C12: 4x 16/16 mm2 | D12: =E12*$E$2 -> 102.85163 | E12: =8943.62/1000 -> 8.94362 | F12: 17/2 | K12: =D104 -> 0.13 | L12: =M104 -> 0.18 | P12: XLPE 0,6/1kV CU | Q12: 4C | R12: 25 | S12: 4075 | T12: 24 | U12: 48 | V12: 169.79167 | X12: MCMK-HF C-PRo 4x25/16 RM 1kV | Y12: 12.272245 | Z12: XCMK-HF C 4x25/16 | AA12: 18.6597 | AB12: =Y12-AA12 -> -6.387455 | AD12: ="XLPE"&" "&"CU"&" "&"-"&" "&X12&" "&AC12 -> XLPE CU - MCMK-HF C-PRo 4x25/16 RM 1kV
B13: XLPE 0,6/1kV CU | C13: 3x 25/16 mm2 | D13: =E13*$E$2 -> 163.44421 | E13: =E14 -> 14.21254 | K13: =D88 -> 0.13 | L13: =M88 -> 0.18 | P13: XLPE 0,6/1kV CU G/Y | Q13: 1C | R13: 35 | S13: 100 | T13: 2 | U13: 4 | V13: 50 | X13: MK-HF C-Pro 35 KEVI | Y13: 3.9188378 | Z13: MK-HF C 35 GNYE H07Z1-R TYPE 2 | AA13: 5.5358 | AB13: =Y13-AA13 -> -1.6169622 | AC13: G/Y | AD13: ="XLPE"&" "&"CU"&" "&"-"&" "&X13&" "&AC13 -> XLPE CU - MK-HF C-Pro 35 KEVI G/Y
B14: XLPE 0,6/1kV CU | C14: 4x 25/16 mm2 | D14: =E14*$E$2 -> 163.44421 | E14: =14212.54/1000 -> 14.21254 | F14: 17/2 | G14: =+E14/E12 -> 1.5891261 | K14: =D103 -> 0.22 | L14: =M103 -> 0.24 | P14: XLPE 0,6/1kV CU | Q14: 4C | R14: 35 | S14: 4090 | T14: 242 | U14: 484 | V14: 16.900826 | X14: MCMK-HF C-PRo 4x35/16 AN 1kV | Y14: 16.385098 | Z14: XCMK-HF C 4x35/16 | AA14: 24.1016 | AB14: =Y14-AA14 -> -7.7165019 | AD14: ="XLPE"&" "&"CU"&" "&"-"&" "&X14&" "&AC14 -> XLPE CU - MCMK-HF C-PRo 4x35/16 AN 1kV
B15: XLPE 0,6/1kV CU | C15: 3x 35/25 mm2 | D15: =E15*$E$2 -> 188.485 | E15: =E16 -> 16.39 | K15: =D87 -> 0.13 | L15: =M87 -> 0.24 | P15: XLPE 0,6/1kV CU | Q15: 1C | R15: 50 | S15: 11120 | T15: 64 | U15: 128 | V15: 173.75 | X15: XMK-HF Cca 1x50 RM 1kV | Y15: 6.1564197 | AA15: 0 | AD15: ="XLPE"&" "&"CU"&" "&"-"&" "&X15&" "&AC15 -> XLPE CU - XMK-HF Cca 1x50 RM 1kV
B16: XLPE 0,6/1kV CU | C16: 4x 35/16 mm2 | D16: =E16*$E$2 -> 188.485 | E16: 16.39 | F16: 29/11 | G16: =+E16/E14 -> 1.153207 | K16: =D102 -> 0.22 | L16: =M102 -> 0.3 | P16: XLPE 0,6/1kV CU | Q16: 4C | R16: 50 | S16: 7975 | T16: 98 | U16: 196 | V16: 81.377551 | X16: MCMK-HF C-PRo 4x50/25 AN 1kV | Y16: 22.016687 | Z16: XCMK-HF C 4x50/25 | AA16: 33.5428 | AB16: =Y16-AA16 -> -11.526113 | AD16: ="XLPE"&" "&"CU"&" "&"-"&" "&X16&" "&AC16 -> XLPE CU - MCMK-HF C-PRo 4x50/25 AN 1kV
B17: XLPE 0,6/1kV CU | C17: 3x 50/25 mm2 | D17: =E17*$E$2 -> 324.84372 | E17: =E18 -> 28.24728 | K17: =D86 -> 0.22 | L17: =M86 -> 0.3 | P17: XLPE 0,6/1kV CU | Q17: 1C | R17: 70 | S17: 6280 | T17: 40 | U17: 72 | V17: 171.11111 | X17: XMK-HF Cca 1x70 RM 1kV | Y17: 8.5159804 | AA17: 0 | AD17: ="XLPE"&" "&"CU"&" "&"-"&" "&X17&" "&AC17 -> XLPE CU - XMK-HF Cca 1x70 RM 1kV
B18: XLPE 0,6/1kV CU | C18: 4x 50/25 mm2 | D18: =E18*$E$2 -> 324.84372 | E18: =28247.28/1000 -> 28.24728 | F18: 17/2 | G18: =+E18/E16 -> 1.723446 | K18: =D101 -> 0.3 | L18: =M101 -> 0.36 | P18: XLPE 0,6/1kV CU | Q18: 4C | R18: 70 | S18: 2800 | T18: 40 | U18: 80 | V18: 70 | X18: MCMK-HF C-PRo 4x70/35 AN 1kV | Y18: 31.558685 | Z18: XCMK-HF C 4x70/35 | AA18: 46.2558 | AB18: =Y18-AA18 -> -14.697115 | AD18: ="XLPE"&" "&"CU"&" "&"-"&" "&X18&" "&AC18 -> XLPE CU - MCMK-HF C-PRo 4x70/35 AN 1kV
B19: XLPE 0,6/1kV CU | C19: 3x 70/35 mm2 | D19: =E19*$E$2 -> 462.56761 | E19: =E20 -> 40.22327 | K19: =D85 -> 0.29 | L19: =M85 -> 0.36 | P19: XLPE 0,6/1kV CU | Q19: 1C | R19: 95 | S19: 6760 | T19: 72 | U19: 144 | V19: 93.888889 | X19: XMK-HF Cca 1x95 RM 1kV | Y19: 11.101971 | AA19: 0 | AD19: ="XLPE"&" "&"CU"&" "&"-"&" "&X19&" "&AC19 -> XLPE CU - XMK-HF Cca 1x95 RM 1kV
B20: XLPE 0,6/1kV CU | C20: 4x 70/35 mm2 | D20: =E20*$E$2 -> 462.56761 | E20: =40223.27/1000 -> 40.22327 | F20: 17/2 | G20: =+E20/E18 -> 1.4239697 | K20: =D100 -> 0.32 | L20: =M100 -> 0.42 | P20: XLPE 0,6/1kV CU | Q20: 4C | R20: 95 | S20: 4550 | T20: 65 | U20: 130 | V20: 70 | X20: MCMK-HF C-PRo 4x95/50 AN 1kV | Y20: 43.542611 | Z20: XCMK-HF C 4x95/50 | AA20: 63.0734 | AB20: =Y20-AA20 -> -19.530789 | AD20: ="XLPE"&" "&"CU"&" "&"-"&" "&X20&" "&AC20 -> XLPE CU - MCMK-HF C-PRo 4x95/50 AN 1kV
B21: XLPE 0,6/1kV CU | C21: 3x 95/50 mm2 | D21: =E21*$E$2 -> 597.25273 | E21: =E22 -> 51.93502 | K21: =D84 -> 0.32 | L21: =M84 -> 0.42 | P21: XLPE 0,6/1kV CU | Q21: 1C | R21: 120 | S21: 1160 | T21: 34 | U21: 68 | V21: 34.117647 | X21: XMK-HF Cca 1x120 RM 1kV | Y21: 14.457398 | AA21: 0 | AB21: =Y21-AA21 -> 14.457398 | AD21: ="XLPE"&" "&"CU"&" "&"-"&" "&X21&" "&AC21 -> XLPE CU - XMK-HF Cca 1x120 RM 1kV
B22: XLPE 0,6/1kV CU | C22: 4x 95/50 mm2 | D22: =E22*$E$2 -> 597.25273 | E22: =51935.02/1000 -> 51.93502 | F22: 17/2 | G22: =+E22/E20 -> 1.2911685 | K22: =D99 -> 0.37 | L22: =M99 -> 0.48 | P22: XLPE 0,6/1kV CU | Q22: 4C | R22: 120 | S22: 360 | T22: 14 | U22: 28 | V22: 25.714286 | X22: MCMK-HF C-PRo 4x120/70 AN 1kV | Y22: 55.165802 | Z22: XCMK-HF C 4x120/70 | AA22: 79.9168 | AB22: =Y22-AA22 -> -24.750998 | AD22: ="XLPE"&" "&"CU"&" "&"-"&" "&X22&" "&AC22 -> XLPE CU - MCMK-HF C-PRo 4x120/70 AN 1kV
B23: XLPE 0,6/1kV CU | C23: 3x 120/70 mm2 | D23: =E23*$E$2 -> 634.455 | E23: =E24 -> 55.17 | K23: =D83 -> 0.35 | L23: =M83 -> 0.45 | P23: XLPE 0,6/1kV CU | Q23: 1C | R23: 185 | S23: 2320 | T23: 44 | U23: 88 | V23: 52.727273 | X23: XMK-HF C-PRo 1x185 AN 1kV | Y23: 18.552132 | AA23: 0 | AD23: ="XLPE"&" "&"CU"&" "&"-"&" "&X23&" "&AC23 -> XLPE CU - XMK-HF C-PRo 1x185 AN 1kV
B24: XLPE 0,6/1kV CU | C24: 4x 120/70 mm2 | D24: =E24*$E$2 -> 634.455 | E24: 55.17 | F24: 29/11 | G24: =+E24/E22 -> 1.062289 | K24: =D98 -> 0.38 | L24: =M98 -> 0.51 | P24: XLPE 0,6/1kV CU | Q24: 1C | R24: 240 | S24: 218060 | T24: 7920 | U24: 15840 | V24: 27.532828 | X24: XMK-HF C-PRo 1x240 AN 1kV | Y24: 23.882078 | AA24: 0 | AD24: ="XLPE"&" "&"CU"&" "&"-"&" "&X24&" "&AC24 -> XLPE CU - XMK-HF C-PRo 1x240 AN 1kV
B25: XLPE 0,6/1kV CU | C25: 3x 150/95 mm2 | D25: =E25*$E$2 -> 824.7915 | E25: =E24*1.3 -> 71.721 | K25: =D82 -> 0.38 | L25: =M82 -> 0.48 | P25: XLPE 0,6/1kV CU G/Y | Q25: 1C | R25: 240 | S25: 25990 | T25: 962 | U25: 1924 | V25: 27.016632 | X25: MKEM-HF C-PRo 240 KEVI | Y25: 24.075818 | Z25: MK-HF C 240 GNYE H07Z1-R TYPE 2 | AA25: 35.6581 | AB25: =Y25-AA25 -> -11.582282 | AC25: G/Y | AD25: ="XLPE"&" "&"CU"&" "&"-"&" "&X25&" "&AC25 -> XLPE CU - MKEM-HF C-PRo 240 KEVI G/Y
B26: XLPE 0,6/1kV CU | C26: 4x 150/95 mm2 | D26: =E26*$E$2 -> 888.237 | E26: =E24*1.4 -> 77.238 | K26: =D97 -> 0.39 | L26: =M97 -> 0.54 | P26: XLPE 0,6/1kV CU | Q26: 4C | R26: 240 | S26: 1430 | T26: 64 | U26: 128 | V26: 22.34375 | X26: MCMK-HF C-PRo 4x240/120 AN 1kV | Y26: 108.50066 | Z26: XCMK-HF C 4x240/120 | AA26: 157.909 | AB26: =Y26-AA26 -> -49.408341 | AD26: ="XLPE"&" "&"CU"&" "&"-"&" "&X26&" "&AC26 -> XLPE CU - MCMK-HF C-PRo 4x240/120 AN 1kV
B27: XLPE 0,6/1kV CU | C27: 3x 185/95 mm2 | D27: =E27*$E$2 -> 1072.229 | E27: =E25*1.3 -> 93.2373 | K27: =D81 -> 0.39 | L27: =M81 -> 0.54 | P27: XLPE 1kV CU | Q27: 1C | R27: 300 | S27: 6960 | T27: 128 | U27: 256 | V27: 54.375 | X27: XMK-HF C-PRo 1x300 AN 1kV | Y27: 32.316781 | AA27: 0 | AD27: ="XLPE"&" "&"CU"&" "&"-"&" "&X27&" "&AC27 -> XLPE CU - XMK-HF C-PRo 1x300 AN 1kV
B28: XLPE 0,6/1kV CU | C28: 4x 185/95 mm2 | D28: =E28*$E$2 -> 1154.7081 | E28: =E25*1.4 -> 100.4094 | K28: =D96 -> 0.4 | L28: =M96 -> 0.6 | P28: XLPE 1kV CU | Q28: 1C | R28: 400 | S28: 9800 | T28: 560 | U28: 1120 | V28: 17.5 | X28: XMK-HF C-PRo 1x400 AN 1kV | Y28: 42.160701 | Z28: MK-HF C 400 GNYE H07Z1-R TYPE 2 | AA28: 59.202 | AB28: =Y28-AA28 -> -17.041299 | AD28: ="XLPE"&" "&"CU"&" "&"-"&" "&X28&" "&AC28 -> XLPE CU - XMK-HF C-PRo 1x400 AN 1kV
B29: XLPE 0,6/1kV CU | C29: 3x 240/120 mm2 | D29: =E29*$E$2 -> 1247.75 | E29: =E30 -> 108.5 | K29: =D80 -> 0.4 | L29: =M80 -> 0.6 | P29: XLPE 0,6/1kV CU Flexible Class 5
B30: XLPE 0,6/1kV CU | C30: 4x 240/120 mm2 | D30: =E30*$E$2 -> 1247.75 | E30: 108.5 | F30: 29/11 | K30: =D95 -> 0.43 | L30: =M95 -> 0.66
C32: 1x 10 mm2 | D32: =E32*$E$2 -> 12.42 | E32: =1080/1000 -> 1.08 | F32: 17/2 | K32: =D77 -> 0.05 | L32: =M77 -> 0.12
B33: XLPE CU G/Y | C33: 1x 16 mm2 | D33: =E33*$E$2 -> 19.09 | E33: =1660/1000 -> 1.66 | F33: 17/2 | K33: =D76 -> 0.05 | L33: =M76 -> 0.15
B34: XLPE CU G/Y | C34: 1x 25 mm2 | D34: =E34*$E$2 -> 29.44 | E34: =2560/1000 -> 2.56 | F34: 17/2 | G34: =+E34/E33-1 -> 0.54216867 | K34: =D75 -> 0.07 | L34: =M75 -> 0.18
B35: XLPE CU G/Y | C35: 1x 35 mm2 | D35: =E35*$E$2 -> 40.94 | E35: =3560/1000 -> 3.56 | F35: 17/2 | G35: =+E35/E34-1 -> 0.390625 | K35: =D74 -> 0.09 | L35: =M74 -> 0.21
B36: XLPE 0,6/1kV CU | C36: 1x 50 mm2 | D36: =E36*$E$2 -> 70.84 | E36: 6.16 | F36: 29/11 | G36: =+E36/E35-1 -> 0.73033708 | K36: =D73 -> 0.12 | L36: =M73 -> 0.24
B37: XLPE 0,6/1kV CU | C37: 1x 70 mm2 | D37: =E37*$E$2 -> 97.98 | E37: 8.52 | F37: 17/2 | G37: =+E37/E36-1 -> 0.38311688 | K37: =D72 -> 0.12 | L37: =M72 -> 0.3
B38: XLPE 0,6/1kV CU | C38: 1x 95 mm2 | D38: =E38*$E$2 -> 127.65 | E38: 11.1 | F38: 29/11 | G38: =+E38/E37-1 -> 0.3028169 | K38: =D71 -> 0.12 | L38: =M71 -> 0.45
B39: XLPE 0,6/1kV CU | C39: 1x 120 mm2 | D39: =E39*$E$2 -> 144.44 | E39: =12560/1000 -> 12.56 | F39: 17/2 | G39: =+E39/E38-1 -> 0.13153153 | K39: =D70 -> 0.13 | L39: =M70 -> 0.6
B40: XLPE 0,6/1kV CU | C40: 1x 150 mm2 | D40: =E40*$E$2 -> 177.64234 | E40: =15447.16/1000 -> 15.44716 | F40: 17/2 | K40: =D69 -> 0.13 | L40: =M69 -> 0.75
B41: XLPE 0,6/1kV CU | C41: 1x 185 mm2 | D41: =E41*$E$2 -> 215.28253 | E41: =18720.22/1000 -> 18.72022 | F41: 17/2 | G41: =+E41/E39-1 -> 0.49046338 | K41: =D68 -> 0.13 | L41: =M68 -> 0.9
B42: XLPE 0,6/1kV CU | C42: 1x 240 mm2 | D42: =E42*$E$2 -> 289.8 | E42: =25200/1000 -> 25.2 | F42: 17/2 | G42: =+E42/E41-1 -> 0.34613803 | K42: =D67 -> 0.22 | L42: =M67 -> 9
...

Sheet Cable trays + Fittings
A1: Code | B1: Type | C1: Material | D1: width | E1: height | G1: Qty. | H1: Unit. Price | I1: Material Price € | J1: Material Price NOK | L1: Time | M1: 0.5 | N1: h* | O1: Qty | P1: Qty/Un
A2: Index: | B2: Cable trays | D2: Fittings
A4: Cable trays:
A5: =CONCATENATE("Cable ",B5," ",C5," ",D5," x ",E5) -> Cable Basket HDG 450 x 60 | B5: Basket | C5: HDG | D5: 450 | E5: 60 | I5: =SUM(I6:I14) -> 37.036421 | J5: =I5*NOK2EUR -> 425.91884 | L5: =IF(D5>300,D5/1000,0.25) -> 0.45 | M5: =$M$1 -> 0.5 | N5: =L5+L5*M5 -> 0.675 | O5: =SUMIF('[55]Cable Trays - maching table'!C:C,A5,'[55]Cable Trays - maching table'!D:D) -> #VALUE!
F6: =CONCATENATE("Cable ",B5," ",C5," ",D5," x ",E5) -> Cable Basket HDG 450 x 60 | G6: 1 | H6: =IF(F6="",0,VLOOKUP(F6,'Cable trays (UnitPrice)'!B:F,5,0)) -> 16.972017 | I6: =H6*G6 -> 16.972017 | P6: =G6*O5 -> #VALUE!
F7: =CONCATENATE(B5," - Union ",C5) -> Basket - Union HDG | G7: 0.7 | H7: =IF(F7="",0,VLOOKUP(F7,'Cable trays (UnitPrice)'!B:F,5,0)) -> 0.68362045 | I7: =H7*G7 -> 0.47853432 | P7: =G7*O5 -> #VALUE!
F8: T-skrue M10x35mm Els MP-983E | G8: 4 | H8: =IF(F8="",0,VLOOKUP(F8,'Cable trays (UnitPrice)'!B:F,5,0)) -> 1.6165217 | I8: =H8*G8 -> 6.466087 | P8: =G8*O5 -> #VALUE!
F9: Hexagonal screw stainless steel, M8 x 30 +Washer M8 | G9: 8 | H9: =IF(F9="",0,VLOOKUP(F9,'Cable trays (UnitPrice)'!B:F,5,0)) -> 0.16434783 | I9: =H9*G9 -> 1.3147826 | P9: =G9*O5 -> #VALUE!
F10: =IF(C5="HDG","Anchor rail 41x41 HDG","Anchor rail 41x41") -> Anchor rail 41x41 HDG | G10: =D5/1000 -> 0.45 | H10: =IF(F10="",0,VLOOKUP(F10,'Cable trays (UnitPrice)'!B:F,5,0)) -> 5.9608696 | I10: =H10*G10 -> 2.6823913 | P10: =G10*O5 -> #VALUE!
F11: ENDEBESKYTTER 41X41MM | G11: 1 | H11: =IF(F11="",0,VLOOKUP(F11,'Cable trays (UnitPrice)'!B:F,5,0)) -> 0.78521739 | I11: =H11*G11 -> 0.78521739 | P11: =G11*O5 -> #VALUE!
F12: =IF(C5="HDG","Ceiling mount for anchor rail Varmf MP-230Z HDG","Ceiling mount for anchor rail Sendz MP-230S") -> Ceiling mount for anchor rail Varmf MP-230Z HDG | G12: 2 | H12: =IF(F12="",0,VLOOKUP(F12,'Cable trays (UnitPrice)'!B:F,5,0)) -> 4.1686957 | I12: =H12*G12 -> 8.3373913 | P12: =G12*O5 -> #VALUE!
H13: =IF(F13="",0,VLOOKUP(F13,'Cable trays (UnitPrice)'!B:F,5,0)) -> 0 | I13: =H13*G13 -> 0 | P13: =G13*O5 -> #VALUE!
H14: =IF(F14="",0,VLOOKUP(F14,'Cable trays (UnitPrice)'!B:F,5,0)) -> 0 | I14: =H14*G14 -> 0 | P14: =G14*O5 -> #VALUE!
A15: =CONCATENATE("Cable ",B15," ",C15," ",D15," x ",E15) -> Cable Basket HDG 450 x 50 | B15: Basket | C15: HDG | D15: 450 | E15: 50 | I15: =SUM(I16:I24) -> 37.020926 | J15: =I15*NOK2EUR -> 425.74064 | L15: =IF(D15>300,D15/1000,0.25) -> 0.45 | M15: =$M$1 -> 0.5 | N15: =L15+L15*M15 -> 0.675 | O15: =SUMIF('[55]Cable Trays - maching table'!C:C,A15,'[55]Cable Trays - maching table'!D:D) -> #VALUE!
F16: =CONCATENATE("Cable ",B15," ",C15," ",D15," x ",E15) -> Cable Basket HDG 450 x 50 | G16: 1 | H16: =IF(F16="",0,VLOOKUP(F16,'Cable trays (UnitPrice)'!B:F,5,0)) -> 16.956522 | I16: =H16*G16 -> 16.956522 | P16: =G16*O15 -> #VALUE!
F17: =CONCATENATE(B15," - Union ",C15) -> Basket - Union HDG | G17: 0.7 | H17: =IF(F17="",0,VLOOKUP(F17,'Cable trays (UnitPrice)'!B:F,5,0)) -> 0.68362045 | I17: =H17*G17 -> 0.47853432 | P17: =G17*O15 -> #VALUE!
F18: T-skrue M10x35mm Els MP-983E | G18: 4 | H18: =IF(F18="",0,VLOOKUP(F18,'Cable trays (UnitPrice)'!B:F,5,0)) -> 1.6165217 | I18: =H18*G18 -> 6.466087 | P18: =G18*O15 -> #VALUE!
F19: Hexagonal screw stainless steel, M8 x 30 +Washer M8 | G19: 8 | H19: =IF(F19="",0,VLOOKUP(F19,'Cable trays (UnitPrice)'!B:F,5,0)) -> 0.16434783 | I19: =H19*G19 -> 1.3147826 | P19: =G19*O15 -> #VALUE!
F20: =IF(C15="HDG","Anchor rail 41x41 HDG","Anchor rail 41x41") -> Anchor rail 41x41 HDG | G20: =D15/1000 -> 0.45 | H20: =IF(F20="",0,VLOOKUP(F20,'Cable trays (UnitPrice)'!B:F,5,0)) -> 5.9608696 | I20: =H20*G20 -> 2.6823913 | P20: =G20*O15 -> #VALUE!
F21: ENDEBESKYTTER 41X41MM | G21: 1 | H21: =IF(F21="",0,VLOOKUP(F21,'Cable trays (UnitPrice)'!B:F,5,0)) -> 0.78521739 | I21: =H21*G21 -> 0.78521739 | P21: =G21*O15 -> #VALUE!
F22: =IF(C15="HDG","Ceiling mount for anchor rail Varmf MP-230Z HDG","Ceiling mount for anchor rail Sendz MP-230S") -> Ceiling mount for anchor rail Varmf MP-230Z HDG | G22: 2 | H22: =IF(F22="",0,VLOOKUP(F22,'Cable trays (UnitPrice)'!B:F,5,0)) -> 4.1686957 | I22: =H22*G22 -> 8.3373913 | P22: =G22*O15 -> #VALUE!
H23: =IF(F23="",0,VLOOKUP(F23,'Cable trays (UnitPrice)'!B:F,5,0)) -> 0 | I23: =H23*G23 -> 0 | P23: =G23*O15 -> #VALUE!
H24: =IF(F24="",0,VLOOKUP(F24,'Cable trays (UnitPrice)'!B:F,5,0)) -> 0 | I24: =H24*G24 -> 0 | P24: =G24*O15 -> #VALUE!
A25: =CONCATENATE("Cable ",B25," ",C25," ",D25," x ",E25) -> Cable Basket HDG 300 x 100 | B25: Basket | C25: HDG | D25: 300 | E25: 100 | I25: =SUM(I26:I34) -> 30.474621 | J25: =I25*NOK2EUR -> 350.45814 | L25: =IF(D25>300,D25/1000,0.25) -> 0.25 | M25: =$M$1 -> 0.5 | N25: =L25+L25*M25 -> 0.375 | O25: =SUMIF('[55]Cable Trays - maching table'!C:C,A25,'[55]Cable Trays - maching table'!D:D) -> #VALUE!
F26: =CONCATENATE("Cable ",B25," ",C25," ",D25," x ",E25) -> Cable Basket HDG 300 x 100 | G26: 1 | H26: =IF(F26="",0,VLOOKUP(F26,'Cable trays (UnitPrice)'!B:F,5,0)) -> 11.304348 | I26: =H26*G26 -> 11.304348 | P26: =G26*O25 -> #VALUE!
F27: =CONCATENATE(B25," - Union ",C25) -> Basket - Union HDG | G27: 0.7 | H27: =IF(F27="",0,VLOOKUP(F27,'Cable trays (UnitPrice)'!B:F,5,0)) -> 0.68362045 | I27: =H27*G27 -> 0.47853432 | P27: =G27*O25 -> #VALUE!
F28: T-skrue M10x35mm Els MP-983E | G28: 4 | H28: =IF(F28="",0,VLOOKUP(F28,'Cable trays (UnitPrice)'!B:F,5,0)) -> 1.6165217 | I28: =H28*G28 -> 6.466087 | P28: =G28*O25 -> #VALUE!
F29: Hexagonal screw stainless steel, M8 x 30 +Washer M8 | G29: 8 | H29: =IF(F29="",0,VLOOKUP(F29,'Cable trays (UnitPrice)'!B:F,5,0)) -> 0.16434783 | I29: =H29*G29 -> 1.3147826 | P29: =G29*O25 -> #VALUE!
F30: =IF(C25="HDG","Anchor rail 41x41 HDG","Anchor rail 41x41") -> Anchor rail 41x41 HDG | G30: =D25/1000 -> 0.3 | H30: =IF(F30="",0,VLOOKUP(F30,'Cable trays (UnitPrice)'!B:F,5,0)) -> 5.9608696 | I30: =H30*G30 -> 1.7882609 | P30: =G30*O25 -> #VALUE!
F31: ENDEBESKYTTER 41X41MM | G31: 1 | H31: =IF(F31="",0,VLOOKUP(F31,'Cable trays (UnitPrice)'!B:F,5,0)) -> 0.78521739 | I31: =H31*G31 -> 0.78521739 | P31: =G31*O25 -> #VALUE!
F32: =IF(C25="HDG","Ceiling mount for anchor rail Varmf MP-230Z HDG","Ceiling mount for anchor rail Sendz MP-230S") -> Ceiling mount for anchor rail Varmf MP-230Z HDG | G32: 2 | H32: =IF(F32="",0,VLOOKUP(F32,'Cable trays (UnitPrice)'!B:F,5,0)) -> 4.1686957 | I32: =H32*G32 -> 8.3373913 | P32: =G32*O25 -> #VALUE!
H33: =IF(F33="",0,VLOOKUP(F33,'Cable trays (UnitPrice)'!B:F,5,0)) -> 0 | I33: =H33*G33 -> 0 | P33: =G33*O25 -> #VALUE!
H34: =IF(F34="",0,VLOOKUP(F34,'Cable trays (UnitPrice)'!B:F,5,0)) -> 0 | I34: =H34*G34 -> 0 | P34: =G34*O25 -> #VALUE!
A35: =CONCATENATE("Cable ",B35," ",C35," ",D35," x ",E35) -> Cable Basket HDG 300 x 60 | B35: Basket | C35: HDG | D35: 300 | E35: 60 | I35: =SUM(I36:I44) -> 29.661569 | J35: =I35*NOK2EUR -> 341.10804 | L35: =IF(D35>300,D35/1000,0.25) -> 0.25 | M35: =$M$1 -> 0.5 | N35: =L35+L35*M35 -> 0.375 | O35: =SUMIF('[55]Cable Trays - maching table'!C:C,A35,'[55]Cable Trays - maching table'!D:D) -> #VALUE!
F36: =CONCATENATE("Cable ",B35," ",C35," ",D35," x ",E35) -> Cable Basket HDG 300 x 60 | G36: 1 | H36: =IF(F36="",0,VLOOKUP(F36,'Cable trays (UnitPrice)'!B:F,5,0)) -> 10.491295 | I36: =H36*G36 -> 10.491295 | P36: =G36*O35 -> #VALUE!
F37: =CONCATENATE(B35," - Union ",C35) -> Basket - Union HDG | G37: 0.7 | H37: =IF(F37="",0,VLOOKUP(F37,'Cable trays (UnitPrice)'!B:F,5,0)) -> 0.68362045 | I37: =H37*G37 -> 0.47853432 | P37: =G37*O35 -> #VALUE!
F38: T-skrue M10x35mm Els MP-983E | G38: 4 | H38: =IF(F38="",0,VLOOKUP(F38,'Cable trays (UnitPrice)'!B:F,5,0)) -> 1.6165217 | I38: =H38*G38 -> 6.466087 | P38: =G38*O35 -> #VALUE!
F39: Hexagonal screw stainless steel, M8 x 30 +Washer M8 | G39: 8 | H39: =IF(F39="",0,VLOOKUP(F39,'Cable trays (UnitPrice)'!B:F,5,0)) -> 0.16434783 | I39: =H39*G39 -> 1.3147826 | P39: =G39*O35 -> #VALUE!
F40: =IF(C35="HDG","Anchor rail 41x41 HDG","Anchor rail 41x41") -> Anchor rail 41x41 HDG | G40: =D35/1000 -> 0.3 | H40: =IF(F40="",0,VLOOKUP(F40,'Cable trays (UnitPrice)'!B:F,5,0)) -> 5.9608696 | I40: =H40*G40 -> 1.7882609 | P40: =G40*O35 -> #VALUE!
F41: ENDEBESKYTTER 41X41MM | G41: 1 | H41: =IF(F41="",0,VLOOKUP(F41,'Cable trays (UnitPrice)'!B:F,5,0)) -> 0.78521739 | I41: =H41*G41 -> 0.78521739 | P41: =G41*O35 -> #VALUE!
...

Sheet Cable trays (UnitPrice)
A1: Pos. | B1: Description | C1: QT | D1: Price NOK | E1: Price EURO | F1: Total Price € | G1: ref. | H1: Supplier | I1: unit | J1: % | K1: Total | L1: Update price date | M1: Total Qty Used | N1: Total € Used - cost | O1: Total € Used - sales
B2: General items | D2: ='[55]Project Input'!E32 -> 11.5 | F2: Cable Trays | G2: Fittings | L2: =SUBTOTAL(3,L4:L1036)/SUBTOTAL(3,I4:I1036) -> 1.0018975 | N2: =SUBTOTAL(9,N4:N931) -> #VALUE! | O2: =#REF! -> #REF! | P2: =N2-N3 -> #VALUE!
N3: 3131529.1 | O3: 3707685.7 | P3: before updated BA price 08.jan
L5: "ctrl + ;" add today date | M5: =SUMIF('Cable trays + Fittings'!F:F,'Cable trays (UnitPrice)'!B5,'Cable trays + Fittings'!P:P) -> 0
M6: =SUMIF('Cable trays + Fittings'!F:F,'Cable trays (UnitPrice)'!B6,'Cable trays + Fittings'!P:P) -> 0
A7: 1. | B7: General items: | M7: =SUMIF('Cable trays + Fittings'!F:F,'Cable trays (UnitPrice)'!B7,'Cable trays + Fittings'!P:P) -> 0 | N7: =M7*F7 -> 0
A8: 1.1 | B8: Miscellaneous | C8: 1 | D8: 1 | E8: =D8/NOK2EUR -> 0.086956522 | F8: =C8*E8 -> 0.086956522 | K8: not found | M8: =SUMIF('Cable trays + Fittings'!F:F,'Cable trays (UnitPrice)'!B8,'Cable trays + Fittings'!P:P) -> 0 | N8: =M8*F8 -> 0 | R8: 1 | S8: =D8-R8 -> 0
A9: 1.2 | B9: Support | C9: 1 | D9: 390 | E9: =D9/NOK2EUR -> 33.913043 | F9: =C9*E9 -> 33.913043 | K9: not found | M9: =SUMIF('Cable trays + Fittings'!F:F,'Cable trays (UnitPrice)'!B9,'Cable trays + Fittings'!P:P) -> 0 | N9: =M9*F9 -> 0 | R9: 390 | S9: =D9-R9 -> 0
A10: 1.3 | B10: T-skrue M10x35mm Els MP-983E | C10: 1 | D10: =K10 -> 18.59 | E10: =D10/NOK2EUR -> 1.6165217 | F10: =C10*E10 -> 1.6165217 | I10: un | K10: 18.59 | L10: 45665 | M10: =SUMIF('Cable trays + Fittings'!F:F,'Cable trays (UnitPrice)'!B10,'Cable trays + Fittings'!P:P) -> #VALUE! | N10: =M10*F10 -> #VALUE! | R10: 22.76 | S10: =D10-R10 -> -4.17
A11: 1.4 | B11: Hexagonal screw stainless steel, M8 x 30 +Washer M8 | C11: 1 | D11: =0.21+1.68 -> 1.89 | E11: =D11/NOK2EUR -> 0.16434783 | F11: =C11*E11 -> 0.16434783 | I11: un | K11: not found | L11: 45665 | M11: =SUMIF('Cable trays + Fittings'!F:F,'Cable trays (UnitPrice)'!B11,'Cable trays + Fittings'!P:P) -> #VALUE! | N11: =M11*F11 -> #VALUE! | R11: 31.2 | S11: =D11-R11 -> -29.31
A12: 1.5 | B12: Anchor rail 41x21 | C12: 1 | D12: 58.3 | E12: =D12/NOK2EUR -> 5.0695652 | F12: =C12*E12 -> 5.0695652 | K12: not found | M12: =SUMIF('Cable trays + Fittings'!F:F,'Cable trays (UnitPrice)'!B12,'Cable trays + Fittings'!P:P) -> 0 | N12: =M12*F12 -> 0 | R12: 58.3 | S12: =D12-R12 -> 0
A13: 1.6 | B13: Anchor rail 41x41 | C13: 1 | D13: =K13 -> 47 | E13: =D13/NOK2EUR -> 4.0869565 | F13: =C13*E13 -> 4.0869565 | I13: un | K13: 47 | L13: 45665 | M13: =SUMIF('Cable trays + Fittings'!F:F,'Cable trays (UnitPrice)'!B13,'Cable trays + Fittings'!P:P) -> #VALUE! | N13: =M13*F13 -> #VALUE! | R13: =89.2*1.1 -> 98.12 | S13: =D13-R13 -> -51.12
A14: 1.7 | B14: Anchor rail 41x41 HDG | C14: 1 | D14: =K14 -> 68.55 | E14: =D14/NOK2EUR -> 5.9608696 | F14: =C14*E14 -> 5.9608696 | I14: un | K14: 68.55 | L14: 45665 | M14: =SUMIF('Cable trays + Fittings'!F:F,'Cable trays (UnitPrice)'!B14,'Cable trays + Fittings'!P:P) -> #VALUE! | N14: =M14*F14 -> #VALUE! | R14: =132*1.1 -> 145.2 | S14: =D14-R14 -> -76.65
A15: 1.8 | B15: Ankerskinne Anchor rail 41x41 Sendz MP-233S | C15: 1 | D15: =76.1/3 -> 25.366667 | E15: =D15/NOK2EUR -> 2.2057971 | F15: =C15*E15 -> 2.2057971 | G15: 1353837 | I15: un | K15: not found | L15: 45624 | M15: =SUMIF('Cable trays + Fittings'!F:F,'Cable trays (UnitPrice)'!B15,'Cable trays + Fittings'!P:P) -> 0 | N15: =M15*F15 -> 0 | R15: =76.1/3 -> 25.366667 | S15: =D15-R15 -> 0
A16: 1.9 | B16: ENDEBESKYTTER 41X41MM | C16: 1 | D16: =K16 -> 9.03 | E16: =D16/NOK2EUR -> 0.78521739 | F16: =C16*E16 -> 0.78521739 | G16: 1353719 | I16: un | K16: 9.03 | L16: 45665 | M16: =SUMIF('Cable trays + Fittings'!F:F,'Cable trays (UnitPrice)'!B16,'Cable trays + Fittings'!P:P) -> #VALUE! | N16: =M16*F16 -> #VALUE! | R16: 34.23 | S16: =D16-R16 -> -25.2
A17: 1.10 | B17: BEND 20MM 90GRAD STÅL 3016122 | C17: 1 | D17: 290 | E17: =D17/NOK2EUR -> 25.217391 | F17: =C17*E17 -> 25.217391 | K17: not found | M17: =SUMIF('Cable trays + Fittings'!F:F,'Cable trays (UnitPrice)'!B17,'Cable trays + Fittings'!P:P) -> 0 | N17: =M17*F17 -> 0 | R17: 290 | S17: =D17-R17 -> 0
A18: 1.11 | B18: Ceiling mount for anchor rail Sendz MP-230S | C18: 1 | D18: =K18 -> 37.32 | E18: =D18/NOK2EUR -> 3.2452174 | F18: =C18*E18 -> 3.2452174 | I18: un | K18: 37.32 | L18: 45665 | M18: =SUMIF('Cable trays + Fittings'!F:F,'Cable trays (UnitPrice)'!B18,'Cable trays + Fittings'!P:P) -> #VALUE! | N18: =M18*F18 -> #VALUE! | R18: 36.25 | S18: =D18-R18 -> 1.07
A19: 1.12 | B19: Ceiling mount for anchor rail Varmf MP-230Z HDG | C19: 1 | D19: =K19 -> 47.94 | E19: =D19/NOK2EUR -> 4.1686957 | F19: =C19*E19 -> 4.1686957 | I19: un | K19: 47.94 | L19: 45665 | M19: =SUMIF('Cable trays + Fittings'!F:F,'Cable trays (UnitPrice)'!B19,'Cable trays + Fittings'!P:P) -> #VALUE! | N19: =M19*F19 -> #VALUE! | R19: 53.04 | S19: =D19-R19 -> -5.1
A20: 1.13 | B20: ELIS FEST BETONGSKRUE 7,5X45C4 | C20: 1 | D20: 5.3 | E20: =D20/NOK2EUR -> 0.46086957 | F20: =C20*E20 -> 0.46086957 | K20: not found | M20: =SUMIF('Cable trays + Fittings'!F:F,'Cable trays (UnitPrice)'!B20,'Cable trays + Fittings'!P:P) -> 0 | N20: =M20*F20 -> 0 | R20: 5.3 | S20: =D20-R20 -> 0
A21: 1.14 | B21: GSV 34 G | C21: 1 | D21: 97.7 | E21: =D21/NOK2EUR -> 8.4956522 | F21: =C21*E21 -> 8.4956522 | K21: not found | M21: =SUMIF('Cable trays + Fittings'!F:F,'Cable trays (UnitPrice)'!B21,'Cable trays + Fittings'!P:P) -> 0 | N21: =M21*F21 -> 0 | R21: 97.7 | S21: =D21-R21 -> 0
